
[2022-04-18 10:24:03]
set_orders
Traceback (most recent call last):
  File "C:\Users\Administrator\AppData\Local\Programs\Python\Python310\lib\site-packages\sqlalchemy\engine\base.py", line 1802, in _execute_context
    self.dialect.do_execute(
  File "C:\Users\Administrator\AppData\Local\Programs\Python\Python310\lib\site-packages\sqlalchemy\engine\default.py", line 719, in do_execute
    cursor.execute(statement, parameters)
  File "C:\Users\Administrator\AppData\Local\Programs\Python\Python310\lib\site-packages\pymysql\cursors.py", line 148, in execute
    result = self._query(query)
  File "C:\Users\Administrator\AppData\Local\Programs\Python\Python310\lib\site-packages\pymysql\cursors.py", line 310, in _query
    conn.query(q)
  File "C:\Users\Administrator\AppData\Local\Programs\Python\Python310\lib\site-packages\pymysql\connections.py", line 548, in query
    self._affected_rows = self._read_query_result(unbuffered=unbuffered)
  File "C:\Users\Administrator\AppData\Local\Programs\Python\Python310\lib\site-packages\pymysql\connections.py", line 775, in _read_query_result
    result.read()
  File "C:\Users\Administrator\AppData\Local\Programs\Python\Python310\lib\site-packages\pymysql\connections.py", line 1156, in read
    first_packet = self.connection._read_packet()
  File "C:\Users\Administrator\AppData\Local\Programs\Python\Python310\lib\site-packages\pymysql\connections.py", line 725, in _read_packet
    packet.raise_for_error()
  File "C:\Users\Administrator\AppData\Local\Programs\Python\Python310\lib\site-packages\pymysql\protocol.py", line 221, in raise_for_error
    err.raise_mysql_exception(self._data)
  File "C:\Users\Administrator\AppData\Local\Programs\Python\Python310\lib\site-packages\pymysql\err.py", line 143, in raise_mysql_exception
    raise errorclass(errno, errval)
pymysql.err.ProgrammingError: (1146, "Table 'cloudprint.fileorder' doesn't exist")

The above exception was the direct cause of the following exception:

Traceback (most recent call last):
  File "d:\enjoyprint\ejy_service\log\except_logger.py", line 10, in wrapper
    return func(*args,**kwargs)
  File "d:\enjoyprint\ejy_service\view\mini\mini.py", line 127, in set_orders
    db.session.commit()
  File "<string>", line 2, in commit
  File "C:\Users\Administrator\AppData\Local\Programs\Python\Python310\lib\site-packages\sqlalchemy\orm\session.py", line 1428, in commit
    self._transaction.commit(_to_root=self.future)
  File "C:\Users\Administrator\AppData\Local\Programs\Python\Python310\lib\site-packages\sqlalchemy\orm\session.py", line 829, in commit
    self._prepare_impl()
  File "C:\Users\Administrator\AppData\Local\Programs\Python\Python310\lib\site-packages\sqlalchemy\orm\session.py", line 808, in _prepare_impl
    self.session.flush()
  File "C:\Users\Administrator\AppData\Local\Programs\Python\Python310\lib\site-packages\sqlalchemy\orm\session.py", line 3345, in flush
    self._flush(objects)
  File "C:\Users\Administrator\AppData\Local\Programs\Python\Python310\lib\site-packages\sqlalchemy\orm\session.py", line 3484, in _flush
    with util.safe_reraise():
  File "C:\Users\Administrator\AppData\Local\Programs\Python\Python310\lib\site-packages\sqlalchemy\util\langhelpers.py", line 70, in __exit__
    compat.raise_(
  File "C:\Users\Administrator\AppData\Local\Programs\Python\Python310\lib\site-packages\sqlalchemy\util\compat.py", line 207, in raise_
    raise exception
  File "C:\Users\Administrator\AppData\Local\Programs\Python\Python310\lib\site-packages\sqlalchemy\orm\session.py", line 3445, in _flush
    flush_context.execute()
  File "C:\Users\Administrator\AppData\Local\Programs\Python\Python310\lib\site-packages\sqlalchemy\orm\unitofwork.py", line 456, in execute
    rec.execute(self)
  File "C:\Users\Administrator\AppData\Local\Programs\Python\Python310\lib\site-packages\sqlalchemy\orm\unitofwork.py", line 630, in execute
    util.preloaded.orm_persistence.save_obj(
  File "C:\Users\Administrator\AppData\Local\Programs\Python\Python310\lib\site-packages\sqlalchemy\orm\persistence.py", line 244, in save_obj
    _emit_insert_statements(
  File "C:\Users\Administrator\AppData\Local\Programs\Python\Python310\lib\site-packages\sqlalchemy\orm\persistence.py", line 1221, in _emit_insert_statements
    result = connection._execute_20(
  File "C:\Users\Administrator\AppData\Local\Programs\Python\Python310\lib\site-packages\sqlalchemy\engine\base.py", line 1614, in _execute_20
    return meth(self, args_10style, kwargs_10style, execution_options)
  File "C:\Users\Administrator\AppData\Local\Programs\Python\Python310\lib\site-packages\sqlalchemy\sql\elements.py", line 325, in _execute_on_connection
    return connection._execute_clauseelement(
  File "C:\Users\Administrator\AppData\Local\Programs\Python\Python310\lib\site-packages\sqlalchemy\engine\base.py", line 1481, in _execute_clauseelement
    ret = self._execute_context(
  File "C:\Users\Administrator\AppData\Local\Programs\Python\Python310\lib\site-packages\sqlalchemy\engine\base.py", line 1845, in _execute_context
    self._handle_dbapi_exception(
  File "C:\Users\Administrator\AppData\Local\Programs\Python\Python310\lib\site-packages\sqlalchemy\engine\base.py", line 2026, in _handle_dbapi_exception
    util.raise_(
  File "C:\Users\Administrator\AppData\Local\Programs\Python\Python310\lib\site-packages\sqlalchemy\util\compat.py", line 207, in raise_
    raise exception
  File "C:\Users\Administrator\AppData\Local\Programs\Python\Python310\lib\site-packages\sqlalchemy\engine\base.py", line 1802, in _execute_context
    self.dialect.do_execute(
  File "C:\Users\Administrator\AppData\Local\Programs\Python\Python310\lib\site-packages\sqlalchemy\engine\default.py", line 719, in do_execute
    cursor.execute(statement, parameters)
  File "C:\Users\Administrator\AppData\Local\Programs\Python\Python310\lib\site-packages\pymysql\cursors.py", line 148, in execute
    result = self._query(query)
  File "C:\Users\Administrator\AppData\Local\Programs\Python\Python310\lib\site-packages\pymysql\cursors.py", line 310, in _query
    conn.query(q)
  File "C:\Users\Administrator\AppData\Local\Programs\Python\Python310\lib\site-packages\pymysql\connections.py", line 548, in query
    self._affected_rows = self._read_query_result(unbuffered=unbuffered)
  File "C:\Users\Administrator\AppData\Local\Programs\Python\Python310\lib\site-packages\pymysql\connections.py", line 775, in _read_query_result
    result.read()
  File "C:\Users\Administrator\AppData\Local\Programs\Python\Python310\lib\site-packages\pymysql\connections.py", line 1156, in read
    first_packet = self.connection._read_packet()
  File "C:\Users\Administrator\AppData\Local\Programs\Python\Python310\lib\site-packages\pymysql\connections.py", line 725, in _read_packet
    packet.raise_for_error()
  File "C:\Users\Administrator\AppData\Local\Programs\Python\Python310\lib\site-packages\pymysql\protocol.py", line 221, in raise_for_error
    err.raise_mysql_exception(self._data)
  File "C:\Users\Administrator\AppData\Local\Programs\Python\Python310\lib\site-packages\pymysql\err.py", line 143, in raise_mysql_exception
    raise errorclass(errno, errval)
sqlalchemy.exc.ProgrammingError: (pymysql.err.ProgrammingError) (1146, "Table 'cloudprint.fileorder' doesn't exist")
[SQL: INSERT INTO fileorder (order_id, file_id, file_name, file_type, file_type_id, duplex, print_color, print_count, print_price, size, create_time, timestamp) VALUES (%(order_id)s, %(file_id)s, %(file_name)s, %(file_type)s, %(file_type_id)s, %(duplex)s, %(print_color)s, %(print_count)s, %(print_price)s, %(size)s, now(), %(timestamp)s)]
[parameters: {'order_id': '20220418mprSDPEXIK1sobW', 'file_id': '20220418N5Db5tzgZ6ngGyh', 'file_name': 'cts-logo', 'file_type': 'png', 'file_type_id': 4, 'duplex': 1, 'print_color': 1, 'print_count': 1, 'print_price': 0.05, 'size': 'A4', 'timestamp': 1650248560}]
(Background on this error at: https://sqlalche.me/e/14/f405)

[2022-04-18 10:26:04]
set_orders
Traceback (most recent call last):
  File "d:\enjoyprint\ejy_service\log\except_logger.py", line 10, in wrapper
    return func(*args,**kwargs)
  File "d:\enjoyprint\ejy_service\view\mini\mini.py", line 128, in set_orders
    orders = Order(order_id=order_id,order_type=order_type,store_id=store_id,file_count=file_count, printer_name=printer_name,price=price,print_situation_code=print_situation_code, print_situation=print_situation,take_id=take_id, openid=openid)
TypeError: __init__() missing 1 required positional argument: 'store_name'

